{"componentChunkName":"component---src-templates-blog-by-tag-js","path":"/posts/exception","result":{"data":{"allMarkdownRemark":{"edges":[{"node":{"excerpt":"In this part we will cover the exception handling for async programming in Scala with Futures.  Part 1. Coding.  Part 2. Exception Handling…","fields":{"slug":"/p/writing-async-app-in-scala-part-2-exception-handling/"},"frontmatter":{"date":"May 24, 2020","title":"Writing Async App in Scala. Part 2: Exception Handling","description":"How to propagate errors in async world? What are caveats of using exceptions in async programming? Use exceptions as a primary propagation mechanism while being on a safe side."}}},{"node":{"excerpt":"UPD: Apparently in top5 from Google there are no correct examples, changed text accordingly. Resource management is a very important topic…","fields":{"slug":"/p/scala-try-with-resources/"},"frontmatter":{"date":"March 12, 2018","title":"Scala try-with-resources","description":"My 2 cents on how to properly manage resources in Scala, or a story of reimplementing try-with-resources in Scala."}}}]}},"pageContext":{"tag":"exception"}}}